{"uuid": "17fb48ab-5251-4964-8c95-6d7925a38450", "children": ["b263e4f6-d30e-4b89-9441-3062f8c9ec17"], "befores": [{"name": "exception_fixture", "status": "broken", "statusDetails": {"message": "Exception: exception\n", "trace": "  File \"/Users/ch/dev/sdet19py/sdet19/.virtualenv/lib/python3.8/site-packages/pluggy/callers.py\", line 187, in _multicall\n    res = hook_impl.function(*args)\n  File \"/Users/ch/dev/sdet19py/sdet19/.virtualenv/lib/python3.8/site-packages/_pytest/fixtures.py\", line 1126, in pytest_fixture_setup\n    result = call_fixture_func(fixturefunc, request, kwargs)\n  File \"/Users/ch/dev/sdet19py/sdet19/.virtualenv/lib/python3.8/site-packages/_pytest/fixtures.py\", line 925, in call_fixture_func\n    fixture_result = next(generator)\n  File \"/Users/ch/dev/sdet19py/sdet19/practice/pytests/test_exception.py\", line 14, in exception_fixture\n    raise Exception(\"exception\")\n"}, "start": 1627199571346, "stop": 1627199571347}], "start": 1627199571346, "stop": 1627199571472}