{"uuid": "103aed10-c757-4f4b-bef2-1769087e8636", "children": ["500c70a0-cee0-42f9-9368-ea1fbaf38c8e"], "befores": [{"name": "exception_fixture", "status": "broken", "statusDetails": {"message": "Exception: exception\n", "trace": "  File \"/Users/ch/dev/sdet19py/sdet19/.virtualenv/lib/python3.8/site-packages/pluggy/callers.py\", line 187, in _multicall\n    res = hook_impl.function(*args)\n  File \"/Users/ch/dev/sdet19py/sdet19/.virtualenv/lib/python3.8/site-packages/_pytest/fixtures.py\", line 1126, in pytest_fixture_setup\n    result = call_fixture_func(fixturefunc, request, kwargs)\n  File \"/Users/ch/dev/sdet19py/sdet19/.virtualenv/lib/python3.8/site-packages/_pytest/fixtures.py\", line 925, in call_fixture_func\n    fixture_result = next(generator)\n  File \"/Users/ch/dev/sdet19py/sdet19/practice/pytests/test_exception.py\", line 14, in exception_fixture\n    raise Exception(\"exception\")\n"}, "start": 1627199678110, "stop": 1627199678110}], "start": 1627199678110, "stop": 1627199678115}