{"uuid": "a13f09cc-0e2f-440a-a22d-3d481f5b0da5", "children": ["b05af528-61d0-4935-b089-9d0087ff04bf"], "befores": [{"name": "exception_fixture", "status": "broken", "statusDetails": {"message": "Exception: exception\n", "trace": "  File \"/Users/ch/dev/sdet19py/sdet19/.virtualenv/lib/python3.8/site-packages/pluggy/callers.py\", line 187, in _multicall\n    res = hook_impl.function(*args)\n  File \"/Users/ch/dev/sdet19py/sdet19/.virtualenv/lib/python3.8/site-packages/_pytest/fixtures.py\", line 1126, in pytest_fixture_setup\n    result = call_fixture_func(fixturefunc, request, kwargs)\n  File \"/Users/ch/dev/sdet19py/sdet19/.virtualenv/lib/python3.8/site-packages/_pytest/fixtures.py\", line 925, in call_fixture_func\n    fixture_result = next(generator)\n  File \"/Users/ch/dev/sdet19py/sdet19/practice/pytests/test_exception.py\", line 14, in exception_fixture\n    raise Exception(\"exception\")\n"}, "start": 1627199625187, "stop": 1627199625188}], "start": 1627199625187, "stop": 1627199625193}