{"uuid": "aaf635b6-698a-41d2-a40d-ec275f941fac", "children": ["2caddeca-8dbf-4914-b778-9ad94a23ca27"], "befores": [{"name": "exception_fixture", "status": "broken", "statusDetails": {"message": "Exception: exception\n", "trace": "  File \"/Users/ch/dev/sdet19py/sdet19/.virtualenv/lib/python3.8/site-packages/pluggy/callers.py\", line 187, in _multicall\n    res = hook_impl.function(*args)\n  File \"/Users/ch/dev/sdet19py/sdet19/.virtualenv/lib/python3.8/site-packages/_pytest/fixtures.py\", line 1126, in pytest_fixture_setup\n    result = call_fixture_func(fixturefunc, request, kwargs)\n  File \"/Users/ch/dev/sdet19py/sdet19/.virtualenv/lib/python3.8/site-packages/_pytest/fixtures.py\", line 925, in call_fixture_func\n    fixture_result = next(generator)\n  File \"/Users/ch/dev/sdet19py/sdet19/practice/pytests/test_exception.py\", line 14, in exception_fixture\n    raise Exception(\"exception\")\n"}, "start": 1627199391482, "stop": 1627199391482}], "start": 1627199391482, "stop": 1627199391631}